[2023-09-04T17:57:42.312+0000] {taskinstance.py:1159} INFO - Dependencies all met for dep_context=non-requeueable deps ti=<TaskInstance: s3_upload.get_monthly_games manual__2023-09-04T17:57:41.311038+00:00 [queued]>
[2023-09-04T17:57:42.322+0000] {taskinstance.py:1159} INFO - Dependencies all met for dep_context=requeueable deps ti=<TaskInstance: s3_upload.get_monthly_games manual__2023-09-04T17:57:41.311038+00:00 [queued]>
[2023-09-04T17:57:42.326+0000] {taskinstance.py:1361} INFO - Starting attempt 1 of 1
[2023-09-04T17:57:42.338+0000] {taskinstance.py:1382} INFO - Executing <Task(PythonOperator): get_monthly_games> on 2023-09-04 17:57:41.311038+00:00
[2023-09-04T17:57:42.345+0000] {standard_task_runner.py:57} INFO - Started process 822 to run task
[2023-09-04T17:57:42.351+0000] {standard_task_runner.py:84} INFO - Running: ['***', 'tasks', 'run', 's3_upload', 'get_monthly_games', 'manual__2023-09-04T17:57:41.311038+00:00', '--job-id', '38', '--raw', '--subdir', 'DAGS_FOLDER/s3_upload.py', '--cfg-path', '/tmp/tmpcz86o1b6']
[2023-09-04T17:57:42.353+0000] {standard_task_runner.py:85} INFO - Job 38: Subtask get_monthly_games
[2023-09-04T17:57:42.420+0000] {task_command.py:415} INFO - Running <TaskInstance: s3_upload.get_monthly_games manual__2023-09-04T17:57:41.311038+00:00 [running]> on host 0f3e7eb4507c
[2023-09-04T17:57:42.490+0000] {taskinstance.py:1660} INFO - Exporting env vars: AIRFLOW_CTX_DAG_OWNER='***' AIRFLOW_CTX_DAG_ID='s3_upload' AIRFLOW_CTX_TASK_ID='get_monthly_games' AIRFLOW_CTX_EXECUTION_DATE='2023-09-04T17:57:41.311038+00:00' AIRFLOW_CTX_TRY_NUMBER='1' AIRFLOW_CTX_DAG_RUN_ID='manual__2023-09-04T17:57:41.311038+00:00'
[2023-09-04T17:57:42.758+0000] {taskinstance.py:1943} ERROR - Task failed with exception
Traceback (most recent call last):
  File "/home/airflow/.local/lib/python3.8/site-packages/airflow/operators/python.py", line 192, in execute
    return_value = self.execute_callable()
  File "/home/airflow/.local/lib/python3.8/site-packages/airflow/operators/python.py", line 209, in execute_callable
    return self.python_callable(*self.op_args, **self.op_kwargs)
  File "/opt/airflow/dags/s3_upload.py", line 30, in get_monthly_games
    with open('/Users/nicholas.goldberg/chess-analytics/Airflow/data/raw_monthly_games.json', 'w') as f:
FileNotFoundError: [Errno 2] No such file or directory: '/Users/nicholas.goldberg/chess-analytics/Airflow/data/raw_monthly_games.json'
[2023-09-04T17:57:42.774+0000] {taskinstance.py:1400} INFO - Marking task as FAILED. dag_id=s3_upload, task_id=get_monthly_games, execution_date=20230904T175741, start_date=20230904T175742, end_date=20230904T175742
[2023-09-04T17:57:42.788+0000] {standard_task_runner.py:104} ERROR - Failed to execute job 38 for task get_monthly_games ([Errno 2] No such file or directory: '/Users/nicholas.goldberg/chess-analytics/Airflow/data/raw_monthly_games.json'; 822)
[2023-09-04T17:57:42.814+0000] {local_task_job_runner.py:228} INFO - Task exited with return code 1
[2023-09-04T17:57:42.846+0000] {taskinstance.py:2784} INFO - 0 downstream tasks scheduled from follow-on schedule check
