[2023-09-04T19:44:04.486+0000] {taskinstance.py:1159} INFO - Dependencies all met for dep_context=non-requeueable deps ti=<TaskInstance: s3_upload_xcom.upload_to_s3_monthly manual__2023-09-04T19:43:58.041533+00:00 [queued]>
[2023-09-04T19:44:04.491+0000] {taskinstance.py:1159} INFO - Dependencies all met for dep_context=requeueable deps ti=<TaskInstance: s3_upload_xcom.upload_to_s3_monthly manual__2023-09-04T19:43:58.041533+00:00 [queued]>
[2023-09-04T19:44:04.491+0000] {taskinstance.py:1361} INFO - Starting attempt 1 of 1
[2023-09-04T19:44:04.497+0000] {taskinstance.py:1382} INFO - Executing <Task(S3CreateObjectOperator): upload_to_s3_monthly> on 2023-09-04 19:43:58.041533+00:00
[2023-09-04T19:44:04.500+0000] {standard_task_runner.py:57} INFO - Started process 433 to run task
[2023-09-04T19:44:04.503+0000] {standard_task_runner.py:84} INFO - Running: ['***', 'tasks', 'run', 's3_upload_xcom', 'upload_to_s3_monthly', 'manual__2023-09-04T19:43:58.041533+00:00', '--job-id', '64', '--raw', '--subdir', 'DAGS_FOLDER/s3_upload_xcom.py', '--cfg-path', '/tmp/tmp3h6gy_3w']
[2023-09-04T19:44:04.504+0000] {standard_task_runner.py:85} INFO - Job 64: Subtask upload_to_s3_monthly
[2023-09-04T19:44:04.534+0000] {task_command.py:415} INFO - Running <TaskInstance: s3_upload_xcom.upload_to_s3_monthly manual__2023-09-04T19:43:58.041533+00:00 [running]> on host a4701647eeb7
[2023-09-04T19:44:04.587+0000] {taskinstance.py:1660} INFO - Exporting env vars: AIRFLOW_CTX_DAG_OWNER='***' AIRFLOW_CTX_DAG_ID='s3_upload_xcom' AIRFLOW_CTX_TASK_ID='upload_to_s3_monthly' AIRFLOW_CTX_EXECUTION_DATE='2023-09-04T19:43:58.041533+00:00' AIRFLOW_CTX_TRY_NUMBER='1' AIRFLOW_CTX_DAG_RUN_ID='manual__2023-09-04T19:43:58.041533+00:00'
[2023-09-04T19:44:04.595+0000] {base.py:73} INFO - Using connection ID 's3_conn' for task execution.
[2023-09-04T19:44:04.596+0000] {connection_wrapper.py:340} INFO - AWS Connection (conn_id='s3_conn', conn_type='aws') credentials retrieved from login and password.
[2023-09-04T19:44:09.050+0000] {taskinstance.py:1943} ERROR - Task failed with exception
Traceback (most recent call last):
  File "/home/airflow/.local/lib/python3.8/site-packages/airflow/providers/amazon/aws/operators/s3.py", line 399, in execute
    s3_hook.load_string(
  File "/home/airflow/.local/lib/python3.8/site-packages/airflow/providers/amazon/aws/hooks/s3.py", line 138, in wrapper
    return func(*bound_args.args, **bound_args.kwargs)
  File "/home/airflow/.local/lib/python3.8/site-packages/airflow/providers/amazon/aws/hooks/s3.py", line 92, in wrapper
    return func(*bound_args.args, **bound_args.kwargs)
  File "/home/airflow/.local/lib/python3.8/site-packages/airflow/providers/amazon/aws/hooks/s3.py", line 1126, in load_string
    self._upload_file_obj(file_obj, key, bucket_name, replace, encrypt, acl_policy)
  File "/home/airflow/.local/lib/python3.8/site-packages/airflow/providers/amazon/aws/hooks/s3.py", line 1202, in _upload_file_obj
    raise ValueError(f"The key {key} already exists.")
ValueError: The key raw_monthly_games.json already exists.
[2023-09-04T19:44:09.077+0000] {taskinstance.py:1400} INFO - Marking task as FAILED. dag_id=s3_upload_xcom, task_id=upload_to_s3_monthly, execution_date=20230904T194358, start_date=20230904T194404, end_date=20230904T194409
[2023-09-04T19:44:09.092+0000] {standard_task_runner.py:104} ERROR - Failed to execute job 64 for task upload_to_s3_monthly (The key raw_monthly_games.json already exists.; 433)
[2023-09-04T19:44:09.133+0000] {local_task_job_runner.py:228} INFO - Task exited with return code 1
[2023-09-04T19:44:09.156+0000] {taskinstance.py:2784} INFO - 0 downstream tasks scheduled from follow-on schedule check
