[2023-09-04T17:59:12.820+0000] {taskinstance.py:1159} INFO - Dependencies all met for dep_context=non-requeueable deps ti=<TaskInstance: s3_upload.get_blitz_game_statistics manual__2023-09-04T17:59:11.419489+00:00 [queued]>
[2023-09-04T17:59:12.831+0000] {taskinstance.py:1159} INFO - Dependencies all met for dep_context=requeueable deps ti=<TaskInstance: s3_upload.get_blitz_game_statistics manual__2023-09-04T17:59:11.419489+00:00 [queued]>
[2023-09-04T17:59:12.831+0000] {taskinstance.py:1361} INFO - Starting attempt 1 of 1
[2023-09-04T17:59:12.848+0000] {taskinstance.py:1382} INFO - Executing <Task(PythonOperator): get_blitz_game_statistics> on 2023-09-04 17:59:11.419489+00:00
[2023-09-04T17:59:12.855+0000] {standard_task_runner.py:57} INFO - Started process 858 to run task
[2023-09-04T17:59:12.860+0000] {standard_task_runner.py:84} INFO - Running: ['***', 'tasks', 'run', 's3_upload', 'get_blitz_game_statistics', 'manual__2023-09-04T17:59:11.419489+00:00', '--job-id', '45', '--raw', '--subdir', 'DAGS_FOLDER/s3_upload.py', '--cfg-path', '/tmp/tmpfov5a7lq']
[2023-09-04T17:59:12.864+0000] {standard_task_runner.py:85} INFO - Job 45: Subtask get_blitz_game_statistics
[2023-09-04T17:59:12.941+0000] {task_command.py:415} INFO - Running <TaskInstance: s3_upload.get_blitz_game_statistics manual__2023-09-04T17:59:11.419489+00:00 [running]> on host 0f3e7eb4507c
[2023-09-04T17:59:13.034+0000] {taskinstance.py:1660} INFO - Exporting env vars: AIRFLOW_CTX_DAG_OWNER='***' AIRFLOW_CTX_DAG_ID='s3_upload' AIRFLOW_CTX_TASK_ID='get_blitz_game_statistics' AIRFLOW_CTX_EXECUTION_DATE='2023-09-04T17:59:11.419489+00:00' AIRFLOW_CTX_TRY_NUMBER='1' AIRFLOW_CTX_DAG_RUN_ID='manual__2023-09-04T17:59:11.419489+00:00'
[2023-09-04T17:59:13.268+0000] {taskinstance.py:1943} ERROR - Task failed with exception
Traceback (most recent call last):
  File "/home/airflow/.local/lib/python3.8/site-packages/airflow/operators/python.py", line 192, in execute
    return_value = self.execute_callable()
  File "/home/airflow/.local/lib/python3.8/site-packages/airflow/operators/python.py", line 209, in execute_callable
    return self.python_callable(*self.op_args, **self.op_kwargs)
  File "/opt/airflow/dags/s3_upload.py", line 46, in get_blitz_game_statistics
    with open('/Users/nicholas.goldberg/chess-analytics/Airflow/data/raw_chess_blitz_statistics.json', 'w') as f:
FileNotFoundError: [Errno 2] No such file or directory: '/Users/nicholas.goldberg/chess-analytics/Airflow/data/raw_chess_blitz_statistics.json'
[2023-09-04T17:59:13.287+0000] {taskinstance.py:1400} INFO - Marking task as FAILED. dag_id=s3_upload, task_id=get_blitz_game_statistics, execution_date=20230904T175911, start_date=20230904T175912, end_date=20230904T175913
[2023-09-04T17:59:13.309+0000] {standard_task_runner.py:104} ERROR - Failed to execute job 45 for task get_blitz_game_statistics ([Errno 2] No such file or directory: '/Users/nicholas.goldberg/chess-analytics/Airflow/data/raw_chess_blitz_statistics.json'; 858)
[2023-09-04T17:59:13.354+0000] {local_task_job_runner.py:228} INFO - Task exited with return code 1
[2023-09-04T17:59:13.401+0000] {taskinstance.py:2784} INFO - 0 downstream tasks scheduled from follow-on schedule check
